<?xml version="1.0"?>
<robot name="robot_diff" xmlns:xacro="http://ros.org/wiki/urdf">
 <link name="base_link">
 </link>
 <link name="Base">
  <visual>
    <origin xyz="0 0 0" rpy="0 0 0 " />
    <geometry>
	    <mesh filename="package://manipulator_description/meshes/base_fix.dae" />
    </geometry>
  </visual>
  <collision>
    <origin xyz="0 0 0" rpy="0 0 0 " />
    <geometry>
	    <mesh filename="package://manipulator_description/meshes/base_fix.dae" />
    </geometry>
  </collision>
  <inertial>
    <origin xyz="0 0 0" rpy="0 0 0 "/>
    <mass value="2.6"/>
    <inertia ixx="7.77716e+3"  ixy="0.00000e+0"  ixz="0.00000e+0" iyy="4.619e+4" iyz="0.00000e+0" izz="5.29561e+4" />
  </inertial>
  </link>
  <joint name="Base_to_base" type="fixed">
    <parent link="base_link"/>
    <child link="Base"/>
    <origin xyz="0.0 0.0 0.0" rpy="0 0 0" />
  </joint>
  
  <!-- Motor 1 -->
  <link name="Motor1">
    <visual>
      <origin xyz="0 0 0" rpy="0 0 0" />
      <geometry>
	      <mesh filename="package://manipulator_description/meshes/motor1.dae" />
      </geometry>
    </visual>
    <collision>
      <origin xyz="0 0 0" rpy="0 0 0 " />
      <geometry>
        <mesh filename="package://manipulator_description/meshes/motor1.dae" />
      </geometry>
    </collision>
    <inertial>
      <origin xyz="0 0 0" rpy="0 0 0 "/>
      <mass value="0.856"/>
      <inertia ixx="1.26094285e-3"  ixy="0.00000e+0"  ixz="0.00000e+0" iyy="3.79002180e-4" iyz="-5.78993250e-9" izz="1.26040377e-3" />
    </inertial>
    </link>
  <joint name="base_motor1" type="fixed">
    <parent link="Base"/>
    <child link="Motor1"/>
    <origin xyz="0 0 0.09" rpy="1.571 0 1.571" />
    <axis xyz="0 0 0" rpy="0 0 0"/>
  </joint>


  <!-- Fix 1 -->
   <!-- <link name="Fix1">
    <visual>
      <origin xyz="0 0 0" rpy="0 0 0" />
      <geometry>
	      <mesh filename="package://manipulator_description/meshes/fix1.dae" />
      </geometry>
    </visual>
    <collision>
      <origin xyz="0 0 0" rpy="0 0 0" />
      <geometry>
        <mesh filename="package://manipulator_description/meshes/fix1.dae" />
      </geometry>
    </collision>
    <inertial>
      <origin xyz="0 0 0" rpy="0 0 0"/>
      <mass value="0.11763625"/>
      <inertia ixx="4.62147e+1"  ixy="-1.98702e-3"  ixz="1.71669e+1" iyy="6.01841e+1" iyz="-3.58878e-3" izz="4.64090e+1" />
    </inertial>
    </link>
  <joint name="motor1_fix1" type="fixed">
    <parent link="Motor1"/>
    <child link="Fix1"/>
    <origin xyz="0.0 0 0.0" rpy="0 0 0" />
  </joint> -->

  <!-- Fix 2 -->
   <!-- <link name="Fix2">
    <visual>
      <origin xyz="-0.045 -0.02 0.027" rpy="0 0 3.14" />
      <geometry>
	      <mesh filename="package://manipulator_description/meshes/fix2.dae" />
      </geometry>
    </visual>
    <collision>
      <origin xyz="-0.045 -0.02 0.027" rpy="0 0 3.14 " />
      <geometry>
        <mesh filename="package://manipulator_description/meshes/fix2.dae" />
      </geometry>
    </collision>
    <inertial>
      <origin xyz="-0.045 -0.02 0.027" rpy="0 0 3.14"/>
      <mass value="0.11763625"/>
      <inertia ixx="4.62147e+1"  ixy="-1.98702e-3"  ixz="1.71669e+1" iyy="6.01841e+1" iyz="-3.58878e-3" izz="4.64090e+1" />
    </inertial>
    </link>
  <joint name="motor1_fix2" type="fixed">
    <parent link="Motor1"/>
    <child link="Fix2"/>
    <origin xyz="0.0 0.0 0.0" rpy="0 0 0" />
  </joint> -->


 <!-- Elo 1 -->
   <link name="Elo1">
    <visual>
      <origin xyz="0 0 0" rpy="0 0 0" />
      <geometry>
	      <mesh filename="package://manipulator_description/meshes/elo1.dae" />
      </geometry>
    </visual>
    <collision>
      <origin xyz="0 0 0" rpy="0 0 0" />
      <geometry>
        <mesh filename="package://manipulator_description/meshes/elo1.dae" />
      </geometry>
    </collision>
    <inertial>
      <origin xyz="0 0 0" rpy="0 0 0"/>
      <mass value="0.15040432"/>
      <inertia ixx="3.45063e+1"  ixy="0.00000e+0"  ixz="0.00000e+0" iyy="1.07762e+2" iyz="0.00000e+0" izz="1.38659e+2" />
    </inertial>
    </link>
  <joint name="motor1_elo1" type="continuous">
    <parent link="Motor1"/>
    <child link="Elo1"/>
    <origin xyz="0.0 0.045 0.0" rpy="1.571 0 0" />
    <axis xyz="0 0 1" rpy="0 0 0"/>
  </joint>


 <!-- Motor 2 -->
  <link name="Motor2">
    <visual>
      <origin xyz="0 0 0" rpy="0 0 0" />
      <geometry>
	      <mesh filename="package://manipulator_description/meshes/motor2.dae" />
      </geometry>
    </visual>
    <collision>
      <origin xyz="0 0 0" rpy="0 0 0" />
      <geometry>
        <mesh filename="package://manipulator_description/meshes/motor2.dae" />
      </geometry>
    </collision>
    <inertial>
      <origin xyz="0 0 0" rpy="0 0 0"/>
      <mass value="0.856"/>
      <inertia ixx="1.26094285e-3"  ixy="0.00000e+0"  ixz="0.00000e+0" iyy="3.79002180e-4" iyz="-5.78993250e-9" izz="1.26040377e-3" />
    </inertial>
    </link>
  <joint name="elo1_motor2" type="fixed">
    <parent link="Elo1"/>
    <child link="Motor2"/>
    <origin xyz="-0.04 0.0 -0.027" rpy="0 1.571 1.571" />
    <axis xyz="0 0 0" rpy="0 0 0"/>
  </joint>


  <!-- Fix Motor2 -->
   <link name="Fix_Motor2">
    <visual>
      <origin xyz="0 0 0" rpy="0 0 0" />
      <geometry>
	      <mesh filename="package://manipulator_description/meshes/fixmotor2.dae" />
      </geometry>
    </visual>
    <collision>
      <origin xyz="0 0 0" rpy="0 0 0 " />
      <geometry>
        <mesh filename="package://manipulator_description/meshes/fixmotor2.dae" />
      </geometry>
    </collision>
    <inertial>
      <origin xyz="0 0 0" rpy="0 0 0"/>
      <mass value="0.03239855"/>
      <inertia ixx="9.57551961e-6"  ixy="-1.52519365e-14"  ixz="7.17291197e-16" iyy="9.41926366e-6" iyz="1.37735170e-11" izz="1.88295847e-5" />
    </inertial>
    </link>
  <joint name="motor2_fix" type="fixed">
    <parent link="Motor2"/>
    <child link="Fix_Motor2"/>
    <origin xyz="0.0 -0.094 0.0" rpy="1.571 0 0" />
  </joint>

   <!-- Frame Motor2 -->
   <link name="Frame_Motor2">
    <visual>
      <origin xyz="0 0 0.03810000" rpy="0 0 0" />
      <geometry>
	      <mesh filename="package://manipulator_description/meshes/framemotor2.dae" />
      </geometry>
    </visual>
    <collision>
      <origin xyz="0 0 0.03810000" rpy="0 0 0 " />
      <geometry>
        <mesh filename="package://manipulator_description/meshes/framemotor2.dae" />
      </geometry>
    </collision>
    <inertial>
      <origin xyz="0 0 0.03810000" rpy="0 0 0"/>
      <mass value="0.04276509"/>
      <inertia ixx="2.60129652e-5"  ixy="5.21881650e-13"  ixz="4.50524013e-6" iyy="2.04411046e-4" iyz="-4.21152332e-14" izz="1.99411922e-4" />
    </inertial>
    </link>
  <joint name="motor2_frame" type="continuous">
    <parent link="Motor2"/>
    <child link="Frame_Motor2"/>
    <origin xyz="0 -0.03 0" rpy="-1.571 0 -1.571" />
    <axis xyz="1 0 0" rpy="0 0 0"/>
  </joint>

   <!-- Elo 2-->
   <link name="Elo2">
    <visual>
      <origin xyz="0 0 0" rpy="0 0 0" />
      <geometry>
	      <mesh filename="package://manipulator_description/meshes/elo2.dae" />
      </geometry>
    </visual>
    <collision>
      <origin xyz="0 0 0" rpy="0 0 0 " />
      <geometry>
        <mesh filename="package://manipulator_description/meshes/elo2.dae" />
      </geometry>
    </collision>
    <inertial>
      <origin xyz="0 0 0" rpy="0 0 0"/>
      <mass value="0.44502800"/>
      <inertia ixx="4.77166e+3"  ixy="-1.92828e+0"  ixz="0.00000e+0" iyy="4.76152e+2" iyz="-7.36178e-4" izz="4.76975e+3" />
    </inertial>
    </link>
  <joint name="frame_elo2" type="fixed">
    <parent link="Frame_Motor2"/>
    <child link="Elo2"/>
    <origin xyz="0.01 0 0.05" rpy="-1.571 0 -1.571" />
    <axis xyz="0 0 0" rpy="0 0 0"/>
  </joint>

</robot>